[2024-05-20T20:11:38.806+0000] {local_task_job_runner.py:120} INFO - ::group::Pre task execution logs
[2024-05-20T20:11:38.893+0000] {taskinstance.py:2076} INFO - Dependencies all met for dep_context=non-requeueable deps ti=<TaskInstance: get_book_dag.get_author_operator manual__2024-05-20T20:06:17.757156+00:00 [queued]>
[2024-05-20T20:11:38.915+0000] {taskinstance.py:2076} INFO - Dependencies all met for dep_context=requeueable deps ti=<TaskInstance: get_book_dag.get_author_operator manual__2024-05-20T20:06:17.757156+00:00 [queued]>
[2024-05-20T20:11:38.916+0000] {taskinstance.py:2306} INFO - Starting attempt 2 of 2
[2024-05-20T20:11:38.955+0000] {taskinstance.py:2330} INFO - Executing <Task(PythonOperator): get_author_operator> on 2024-05-20 20:06:17.757156+00:00
[2024-05-20T20:11:38.971+0000] {warnings.py:110} WARNING - /home/***/.local/lib/python3.12/site-packages/***/task/task_runner/standard_task_runner.py:61: DeprecationWarning: This process (pid=1028) is multi-threaded, use of fork() may lead to deadlocks in the child.
  pid = os.fork()

[2024-05-20T20:11:38.976+0000] {standard_task_runner.py:63} INFO - Started process 1030 to run task
[2024-05-20T20:11:38.975+0000] {standard_task_runner.py:90} INFO - Running: ['***', 'tasks', 'run', 'get_book_dag', 'get_author_operator', 'manual__2024-05-20T20:06:17.757156+00:00', '--job-id', '55', '--raw', '--subdir', 'DAGS_FOLDER/get_book_dag.py', '--cfg-path', '/tmp/tmp_hirg7cw']
[2024-05-20T20:11:38.979+0000] {standard_task_runner.py:91} INFO - Job 55: Subtask get_author_operator
[2024-05-20T20:11:39.118+0000] {task_command.py:426} INFO - Running <TaskInstance: get_book_dag.get_author_operator manual__2024-05-20T20:06:17.757156+00:00 [running]> on host 60554ca90225
[2024-05-20T20:11:39.353+0000] {taskinstance.py:2648} INFO - Exporting env vars: AIRFLOW_CTX_DAG_OWNER='***' AIRFLOW_CTX_DAG_ID='get_book_dag' AIRFLOW_CTX_TASK_ID='get_author_operator' AIRFLOW_CTX_EXECUTION_DATE='2024-05-20T20:06:17.757156+00:00' AIRFLOW_CTX_TRY_NUMBER='2' AIRFLOW_CTX_DAG_RUN_ID='manual__2024-05-20T20:06:17.757156+00:00'
[2024-05-20T20:11:39.357+0000] {taskinstance.py:430} INFO - ::endgroup::
[2024-05-20T20:11:39.430+0000] {taskinstance.py:441} INFO - ::group::Post task execution logs
[2024-05-20T20:11:39.432+0000] {taskinstance.py:2905} ERROR - Task failed with exception
Traceback (most recent call last):
  File "/home/airflow/.local/lib/python3.12/site-packages/airflow/models/taskinstance.py", line 465, in _execute_task
    result = _execute_callable(context=context, **execute_callable_kwargs)
             ^^^^^^^^^^^^^^^^^^^^^^^^^^^^^^^^^^^^^^^^^^^^^^^^^^^^^^^^^^^^^
  File "/home/airflow/.local/lib/python3.12/site-packages/airflow/models/taskinstance.py", line 432, in _execute_callable
    return execute_callable(context=context, **execute_callable_kwargs)
           ^^^^^^^^^^^^^^^^^^^^^^^^^^^^^^^^^^^^^^^^^^^^^^^^^^^^^^^^^^^^
  File "/home/airflow/.local/lib/python3.12/site-packages/airflow/models/baseoperator.py", line 400, in wrapper
    return func(self, *args, **kwargs)
           ^^^^^^^^^^^^^^^^^^^^^^^^^^^
  File "/home/airflow/.local/lib/python3.12/site-packages/airflow/operators/python.py", line 235, in execute
    return_value = self.execute_callable()
                   ^^^^^^^^^^^^^^^^^^^^^^^
  File "/home/airflow/.local/lib/python3.12/site-packages/airflow/operators/python.py", line 252, in execute_callable
    return self.python_callable(*self.op_args, **self.op_kwargs)
           ^^^^^^^^^^^^^^^^^^^^^^^^^^^^^^^^^^^^^^^^^^^^^^^^^^^^^
  File "/opt/airflow/dags/get_book_dag.py", line 39, in get_author_func
    data_ex.to_excel('file.xlsx', sheet_name='Sheet1', index=False)
  File "/home/airflow/.local/lib/python3.12/site-packages/pandas/core/generic.py", line 2345, in to_excel
    formatter.write(
  File "/home/airflow/.local/lib/python3.12/site-packages/pandas/io/formats/excel.py", line 946, in write
    writer = ExcelWriter(  # type: ignore[abstract]
             ^^^^^^^^^^^^^^^^^^^^^^^^^^^^^^^^^^^^^^
  File "/home/airflow/.local/lib/python3.12/site-packages/pandas/io/excel/_openpyxl.py", line 57, in __init__
    from openpyxl.workbook import Workbook
ModuleNotFoundError: No module named 'openpyxl'
[2024-05-20T20:11:39.476+0000] {taskinstance.py:1206} INFO - Marking task as FAILED. dag_id=get_book_dag, task_id=get_author_operator, run_id=manual__2024-05-20T20:06:17.757156+00:00, execution_date=20240520T200617, start_date=20240520T201138, end_date=20240520T201139
[2024-05-20T20:11:39.574+0000] {standard_task_runner.py:110} ERROR - Failed to execute job 55 for task get_author_operator (No module named 'openpyxl'; 1030)
[2024-05-20T20:11:39.617+0000] {local_task_job_runner.py:240} INFO - Task exited with return code 1
[2024-05-20T20:11:39.667+0000] {taskinstance.py:3498} INFO - 0 downstream tasks scheduled from follow-on schedule check
[2024-05-20T20:11:39.679+0000] {local_task_job_runner.py:222} INFO - ::endgroup::
